<!DOCTYPE html>
<html lang="en">

<head>
   <meta charset="UTF-8">
   <meta name="viewport" content="width=device-width, initial-scale=1.0">
   <title>Exception Handling</title>
</head>

<body>

   <div class="container">
      <h2 style="text-align: center;"><span style="color: #ff6600;">Exception Handling</span></h2>
      <p> </p>
      <p>An exception is a problem that arises during the execution of a program. A C++ exception is a response to an
         exceptional circumstance that arises while a program is running, such as an attempt to divide by zero.</p>
      <p>Exceptions provide a way to transfer control from one part of a program to another. C++ exception handling is
         built upon three keywords: <strong>try, catch,</strong> and <strong>throw</strong>.</p>
      <ul>
         <li>
            <p><strong>throw</strong> &minus; A program throws an exception when a problem shows up. This is done using
               a <strong>throw</strong> keyword.</p>
         </li>
         <li>
            <p><strong>catch</strong> &minus; A program catches an exception with an exception handler at the place in a
               program where you want to handle the problem. The <strong>catch</strong> keyword indicates the catching
               of an exception.</p>
         </li>
         <li>
            <p><strong>try</strong> &minus; A <strong>try</strong> block identifies a block of code for which particular
               exceptions will be activated. It's followed by one or more catch blocks.</p>
         </li>
      </ul>
      <p>Assuming a block will raise an exception, a method catches an exception using a combination of the
         <strong>try</strong> and <strong>catch</strong> keywords. A try/catch block is placed around the code that
         might generate an exception.</p>
      <p>Code within a try/catch block is referred to as protected code, and the syntax for using try/catch as follows
         &minus;</p>
      <pre><b>try {
   // protected code
} catch( ExceptionName e1 ) {
   // catch block
} catch( ExceptionName e2 ) {
   // catch block
} catch( ExceptionName eN ) {
   // catch block
}</b>
</pre>
      <p>You can list down multiple <strong>catch</strong> statements to catch different type of exceptions in case your
         <strong>try</strong> block raises more than one exception in different situations.</p>
      <h3>Throwing Exceptions</h3>
      <p>Exceptions can be thrown anywhere within a code block using <strong>throw</strong> statement. The operand of
         the throw statement determines a type for the exception and can be any expression and the type of the result of
         the expression determines the type of exception thrown.</p>
      <p>Following is an example of throwing an exception when dividing by zero condition occurs &minus;</p>
      <pre><b>double division(int a, int b) {
   if( b == 0 ) {
      throw "Division by zero condition!";
   }
   return (a/b);
}</b></pre>
      <h3>Catching Exceptions</h3>
      <p>The <strong>catch</strong> block following the <strong>try</strong> block catches any exception. You can
         specify what type of exception you want to catch and this is determined by the exception declaration that
         appears in parentheses following the keyword catch.</p>
      <pre><b>try {
   // protected code
} catch( ExceptionName e ) {
  // code to handle ExceptionName exception
}</b></pre>
      <p>Above code will catch an exception of <strong>ExceptionName</strong> type. If you want to specify that a catch
         block should handle any type of exception that is thrown in a try block, you must put an ellipsis, ..., between
         the parentheses enclosing the exception declaration as follows &minus;</p>
      <pre><b>try {
   // protected code
} catch(...) {
  // code to handle any exception
}</b></pre>
      <p>The following is an example, which throws a division by zero exception and we catch it in catch block.</p>

      <textarea id="ta" cols="60" rows="10" readonly>
#include <iostream>
using namespace std;
            
double division(int a, int b) {
   if( b == 0 ) {
      throw "Division by zero condition!";
   }
   return (a/b);
}
            
int main () {
   int x = 50;
   int y = 0;
   double z = 0;
 
   try {
      z = division(x, y);
      cout << z << endl;
   } catch (const char* msg) {
     cerr << msg << endl;
   }
            
   return 0;
}
      </textarea>

      <p>Because we are raising an exception of type <strong>const char*</strong>, so while catching this exception, we
         have to use const char* in catch block. If we compile and run above code, this would produce the following
         result &minus;</p>
      <pre><b>Division by zero condition!</b></pre>

      <h3>C++ Standard Exceptions</h3>
      <p>C++ provides a list of standard exceptions defined in <strong>&lt;exception&gt;</strong> which we can use in
         our programs. These are arranged in a parent-child class hierarchy shown below &minus;</p>
      <p>Here is the small description of each exception mentioned in the above hierarchy &minus;</p>
      <table>
         <tbody>
            <tr>
               <th>Sr.No</th>
               <th>Exception &amp; Description</th>
            </tr>
            <tr>
               <td class="ts">1.</td>
               <td>
                  <p><strong>std::exception</strong></p>
                  <p>An exception and parent class of all the standard C++ exceptions.</p>
               </td>
            </tr>
            <tr>
               <td class="ts">2.</td>
               <td>
                  <p><strong>std::bad_alloc</strong></p>
                  <p>This can be thrown by <strong>new</strong>.</p>
               </td>
            </tr>
            <tr>
               <td class="ts">3.</td>
               <td>
                  <p><strong>std::bad_cast</strong></p>
                  <p>This can be thrown by <strong>dynamic_cast</strong>.</p>
               </td>
            </tr>
            <tr>
               <td class="ts">4.</td>
               <td>
                  <p><strong>std::bad_exception</strong></p>
                  <p>This is useful device to handle unexpected exceptions in a C++ program.</p>
               </td>
            </tr>
            <tr>
               <td class="ts">5.</td>
               <td>
                  <p><strong>std::bad_typeid</strong></p>
                  <p>This can be thrown by <strong>typeid</strong>.</p>
               </td>
            </tr>
            <tr>
               <td class="ts">6.</td>
               <td>
                  <p><strong>std::logic_error</strong></p>
                  <p>An exception that theoretically can be detected by reading the code.</p>
               </td>
            </tr>
            <tr>
               <td class="ts">7.</td>
               <td>
                  <p><strong>std::domain_error</strong></p>
                  <p>This is an exception thrown when a mathematically invalid domain is used.</p>
               </td>
            </tr>
            <tr>
               <td class="ts">8.</td>
               <td>
                  <p><strong>std::invalid_argument</strong></p>
                  <p>This is thrown due to invalid arguments.</p>
               </td>
            </tr>
            <tr>
               <td class="ts">9.</td>
               <td>
                  <p><strong>std::length_error</strong></p>
                  <p>This is thrown when a too big std::string is created.</p>
               </td>
            </tr>
            <tr>
               <td class="ts">10.</td>
               <td>
                  <p><strong>std::out_of_range</strong></p>
                  <p>This can be thrown by the 'at' method, for example a std::vector and
                     std::bitset&lt;&gt;::operator[]().</p>
               </td>
            </tr>
            <tr>
               <td class="ts">11.</td>
               <td>
                  <p><strong>std::runtime_error</strong></p>
                  <p>An exception that theoretically cannot be detected by reading the code.</p>
               </td>
            </tr>
            <tr>
               <td class="ts">12.</td>
               <td>
                  <p><strong>std::overflow_error</strong></p>
                  <p>This is thrown if a mathematical overflow occurs.</p>
               </td>
            </tr>
            <tr>
               <td class="ts">13.</td>
               <td>
                  <p><strong>std::range_error</strong></p>
                  <p>This is occurred when you try to store a value which is out of range.</p>
               </td>
            </tr>
            <tr>
               <td class="ts">14.</td>
               <td>
                  <p><strong>std::underflow_error</strong></p>
                  <p>This is thrown if a mathematical underflow occurs.</p>
               </td>
            </tr>
         </tbody>
      </table>
      <h3>Define New Exceptions</h3>
      <p>You can define your own exceptions by inheriting and overriding <strong>exception</strong> class functionality.
         Following is the example, which shows how you can use std::exception class to implement your own exception in
         standard way &minus;</p>

         <textarea id="ta" cols="60" rows="10" readonly>
#include <iostream>
#include <exception>
using namespace std;
               
struct MyException : public exception {
   const char * what () const throw () {
      return "C++ Exception";
   }
};
                
int main() {
   try {
      throw MyException();
   } catch(MyException& e) {
      std::cout << "MyException caught" << std::endl;
      std::cout << e.what() << std::endl;
   } catch(std::exception& e) {
      //Other errors
   }
}
         </textarea>

      <p>This would produce the following result &minus;</p>
      <pre><b>MyException caught
C++ Exception</b>
</pre>
      <p>Here, <strong>what()</strong> is a public method provided by exception class and it has been overridden by all
         the child exception classes. This returns the cause of an exception.</p>

   </div>
</body>

</html>


<style type="text/css">
   @import url('https://fonts.googleapis.com/css2?family=Poppins:wght@500&display=swap');


   body {
      font-family: 'Poppins', sans-serif;
      background-color: #008080;
      padding: 20px;
   }

   .container {
      background: white;
      padding: 20px 50px;
      box-shadow: 2px 2px 25px black;
   }

   #ta {
      color: white;
      background: #25383c;
      padding: 10px 15px;
      resize: none;
   }

   hr {
      width: 100%;
      height: 2px;
   }

   table,
   td,
   th {
      border: 1px solid black;
      border-collapse: collapse;
      padding: 5px 10px;
   }

   .ts {
      text-align: center;
   }



   @media only screen and (max-width: 600px) {
      #ta {
         width: 80%;
         font-size: 10px;
         padding: 7px;
      }

      body {
         padding: 10px;
         font-size: 10px;
      }

      .container {
         box-shadow: 1px 1px 18px;
         padding: 10px;
      }
   }
</style>